Workbook

Sheet Executive Summary
A1: Multi-Cloud FinOps Executive Summary
A3: Total Spend | D3: Base Forecast | G3: Approved Budget | J3: Forecast Variance | M3: Critical Anomalies | Q3: Warning Anomalies | U3: Total Anomaly Impact
A4: =SUM(tblActuals[billed_cost]) -> 139937.52 | D4: =_xlfn.XLOOKUP( "Base", tblScenarios[scenario], tblScenarios[scenario_forecast], 0 ) -> 42687.034 | G4: =_xlfn.XLOOKUP( "Base", tblScenarios[scenario], tblScenarios[approved_budget], 0 ) -> 54751.018 | J4: =_xlfn.XLOOKUP( "Base", tblScenarios[scenario], tblScenarios[variance_to_budget], 0 ) -> -12063.985 | M4: =anomaly_report!D3 -> 1 | Q4: =anomaly_report!F3 -> 2 | U4: =anomaly_report!H3 -> 915.5773
A7: Allocation Coverage % | D7: Unallocated Spend % | G7: Untagged Spend % | J7: Effective Savings Rate
A8: =1-D8 -> 0.92272498 | D8: =IFERROR( SUMIFS( tblActuals[billed_cost], tblActuals[charge_category],"Usage", tblActuals[allocation_method],"Unallocated", tblActuals[billed_cost],">0" ) / SUMIFS( tblActuals[billed_cost], tblActuals[charge_category],"Usage", tblActuals[billed_cost],">0" ), 0 ) -> 0.077275021 | G8: =IFERROR( SUMIFS( tblActuals[billed_cost], tblActuals[charge_category],"Usage", tblActuals[source_allocation_status],"Unallocated", tblActuals[billed_cost],">0" ) / SUMIFS( tblActuals[billed_cost], tblActuals[charge_category],"Usage", tblActuals[billed_cost],">0" ), 0 ) -> 0.077275021 | J8: =IFERROR( 1- SUMIFS( tblActuals[billed_cost], tblActuals[charge_category],"Usage", tblActuals[billed_cost],">0" ) / SUMIFS( tblActuals[list_cost], tblActuals[charge_category],"Usage", tblActuals[list_cost],">0" ), 0 ) -> 0.098465346
A11: Reconciliation Status | D11: Forecast MAPE | G11: High Growth Forecast | J11: Optimization Savings
A12: =Reconciliation!B6 -> PASS | D12: =IFERROR( AVERAGE(tblPriorForecast[absolute_error_pct]), "Pending" ) -> Pending | G12: =_xlfn.XLOOKUP( "High Growth", tblScenarios[scenario], tblScenarios[scenario_forecast], 0 ) -> 49090.089 | J12: =-_xlfn.XLOOKUP( "Optimization", tblScenarios[scenario], tblScenarios[change_vs_base], 0 ) -> 4268.7034
A30: Note: March is a partial reporting month. June actuals are through June 29, 2026.

Sheet Assumptions
A1: Assumptions & Model Controls
A4: Assumption | B4: Value | C4: Unit / Format | D4: Business rationale / source | F4: provider_name | G4: monthly_growth_rate
A5: Reporting date | B5: 46202 | C5: Date | D5: Latest synthetic billing date; update for each refresh | F5: AWS | G5: 0.04
A6: Current run-rate weight | B6: 0.7 | C6: % | D6: Higher weight on current-month behavior 80/20: more responsive to recent changes 50/50: balanced 30/70: more conservative and history-driven | F6: GCP | G6: 0.06
A7: Historical forecast weight | B7: =1-B6 -> 0.3 | C7: % | D7: Formula: 1 minus current run-rate weight
A8: Variance warning threshold | B8: 0.1 | C8: % | D8: Management review threshold
A9: Variance critical threshold | B9: 0.2 | C9: % | D9: Escalation threshold
A10: Expected allocated total | B10: 139937.52 | C10: $ | D10: Python allocation milestone control total
A11: Reconciliation tolerance | B11: 0.01 | C11: $ | D11: Allow only immaterial rounding difference
A12: Forecast history months | B12: 2 | C12: Months | D12: Use two completed months as historical baseline
A13: Input CSV | B13: data\processed\allocated_cost_usage.csv | C13: Path | D13: Curated Python allocation output
A14: Primary cost field | B14: billed_cost | C14: Column | D14: Rename the final allocated amount to this field in Power Query
A15: Budget Baseline Month | B15: 46113
A16: Default Growth Rate | B16: 0.05
A17: High Growth Multiplier | B17: 1.15 | D17: cloud demand becomes 15% higher than the current forecast.
A18: Optimization Savings Rate | B18: 0.1 | D18: rightsizing, scheduling and waste reduction lower forecasted cost by 10%.

Sheet allocated_cost_usage
A1: record_id | B1: provider_name | C1: billing_account_id | D1: sub_account_id | E1: sub_account_name | F1: charge_period_start | G1: charge_period_end | H1: billing_period_start | I1: billing_period_end | J1: service_name | K1: service_category | L1: sku_description | M1: resource_id | N1: region | O1: availability_zone | P1: consumed_quantity | Q1: consumed_unit | R1: list_unit_price | S1: pricing_category | T1: billing_currency | U1: list_cost | V1: billed_cost | W1: effective_cost | X1: charge_category | Y1: charge_class | Z1: charge_description | AA1: tags | AB1: application | AC1: environment | AD1: cost_center | AE1: owner | AF1: allocation_status | AG1: source_file | AH1: source_row_number | AI1: source_allocation_status | AJ1: allocation_method | AK1: allocation_driver | AL1: allocation_weight | AM1: allocation_id | AN1: billing_month | AO1: Date
A2: aws-2026-04-01-111111111111-01-01 | B2: AWS | C2: 999999999999 | D2: 111111111111 | E2: production-account | F2: 46112.833 | G2: 46113.833 | H2: 46112.833 | I2: 46142.833 | J2: Amazon Elastic Compute Cloud - Compute | K2: Compute | L2: BoxUsage:m5.large | M2: i-1111-01-01 | N2: us-east-1 | P2: 1110.1162 | Q2: Hrs | R2: 0.096 | S2: Standard | T2: USD | U2: 106.5712 | V2: 93.2498 | W2: 93.2498 | X2: Usage | Z2: BoxUsage:m5.large | RunInstances | Usage | AA2: {} | AB2: Unallocated | AC2: unknown | AD2: UNALLOCATED | AE2: Unassigned | AF2: Unallocated | AG2: aws_billing_sample.csv | AH2: 2 | AI2: Unallocated | AJ2: Unallocated | AK2: Missing allocation metadata | AL2: 1 | AM2: aws-2026-04-01-111111111111-01-01-alloc-624101d11abd | AN2: 46082 | AO2: 46082
A3: aws-2026-04-01-111111111111-01-02 | B3: AWS | C3: 999999999999 | D3: 111111111111 | E3: production-account | F3: 46112.833 | G3: 46113.833 | H3: 46112.833 | I3: 46142.833 | J3: Amazon Elastic Compute Cloud - Compute | K3: Compute | L3: BoxUsage:m5.large | M3: i-1111-01-02 | N3: us-east-1 | P3: 1031.4063 | Q3: Hrs | R3: 0.096 | S3: Standard | T3: USD | U3: 99.015 | V3: 86.6381 | W3: 86.6381 | X3: Usage | Z3: BoxUsage:m5.large | RunInstances | Usage | AA3: {"application":"Checkout","cost_center":"CC-1001","environment":"production","team":"Payments"} | AB3: Checkout | AC3: production | AD3: CC-1001 | AE3: Payments | AF3: Allocated | AG3: aws_billing_sample.csv | AH3: 3 | AI3: Allocated | AJ3: Direct | AK3: Source tags/labels | AL3: 1 | AM3: aws-2026-04-01-111111111111-01-02-alloc-241880d50a37 | AN3: 46082 | AO3: 46082
A4: aws-2026-04-01-111111111111-02-01 | B4: AWS | C4: 999999999999 | D4: 111111111111 | E4: production-account | F4: 46112.833 | G4: 46113.833 | H4: 46112.833 | I4: 46142.833 | J4: Amazon Simple Storage Service | K4: Storage | L4: TimedStorage-ByteHrs | M4: bucket-1111-02-01 | N4: us-east-1 | P4: 245.0669 | Q4: GB-Mo | R4: 0.023 | S4: Standard | T4: USD | U4: 5.6365 | V4: 5.2689 | W4: 5.2689 | X4: Usage | Z4: TimedStorage-ByteHrs | StandardStorage | Usage | AA4: {"application":"Checkout","cost_center":"CC-1001","environment":"production","team":"Payments"} | AB4: Checkout | AC4: production | AD4: CC-1001 | AE4: Payments | AF4: Allocated | AG4: aws_billing_sample.csv | AH4: 4 | AI4: Allocated | AJ4: Direct | AK4: Source tags/labels | AL4: 1 | AM4: aws-2026-04-01-111111111111-02-01-alloc-cae6faec733d | AN4: 46082 | AO4: 46082
A5: aws-2026-04-01-111111111111-02-02 | B5: AWS | C5: 999999999999 | D5: 111111111111 | E5: production-account | F5: 46112.833 | G5: 46113.833 | H5: 46112.833 | I5: 46142.833 | J5: Amazon Simple Storage Service | K5: Storage | L5: TimedStorage-ByteHrs | M5: bucket-1111-02-02 | N5: us-east-1 | P5: 252.354 | Q5: GB-Mo | R5: 0.023 | S5: Standard | T5: USD | U5: 5.8041 | V5: 5.4256 | W5: 5.4256 | X5: Usage | Z5: TimedStorage-ByteHrs | StandardStorage | Usage | AA5: {"application":"Checkout","cost_center":"CC-1001","environment":"production","team":"Payments"} | AB5: Checkout | AC5: production | AD5: CC-1001 | AE5: Payments | AF5: Allocated | AG5: aws_billing_sample.csv | AH5: 5 | AI5: Allocated | AJ5: Direct | AK5: Source tags/labels | AL5: 1 | AM5: aws-2026-04-01-111111111111-02-02-alloc-376a996a99e4 | AN5: 46082 | AO5: 46082
A6: aws-2026-04-01-111111111111-03-01 | B6: AWS | C6: 999999999999 | D6: 111111111111 | E6: production-account | F6: 46112.833 | G6: 46113.833 | H6: 46112.833 | I6: 46142.833 | J6: Amazon Relational Database Service | K6: Databases | L6: InstanceUsage:db.m5.large | M6: db-1111-03-01 | N6: us-east-1 | P6: 212.627 | Q6: Hrs | R6: 0.192 | S6: Standard | T6: USD | U6: 40.8244 | V6: 36.1466 | W6: 36.1466 | X6: Usage | Z6: InstanceUsage:db.m5.large | CreateDBInstance | Usage | AA6: {} | AB6: Unallocated | AC6: unknown | AD6: UNALLOCATED | AE6: Unassigned | AF6: Unallocated | AG6: aws_billing_sample.csv | AH6: 6 | AI6: Unallocated | AJ6: Unallocated | AK6: Missing allocation metadata | AL6: 1 | AM6: aws-2026-04-01-111111111111-03-01-alloc-a307568d468c | AN6: 46082 | AO6: 46082
A7: aws-2026-04-01-111111111111-03-02 | B7: AWS | C7: 999999999999 | D7: 111111111111 | E7: production-account | F7: 46112.833 | G7: 46113.833 | H7: 46112.833 | I7: 46142.833 | J7: Amazon Relational Database Service | K7: Databases | L7: InstanceUsage:db.m5.large | M7: db-1111-03-02 | N7: us-east-1 | P7: 203.8452 | Q7: Hrs | R7: 0.192 | S7: Standard | T7: USD | U7: 39.1383 | V7: 34.6537 | W7: 34.6537 | X7: Usage | Z7: InstanceUsage:db.m5.large | CreateDBInstance | Usage | AA7: {"application":"Checkout","cost_center":"CC-1001","environment":"production","team":"Payments"} | AB7: Checkout | AC7: production | AD7: CC-1001 | AE7: Payments | AF7: Allocated | AG7: aws_billing_sample.csv | AH7: 7 | AI7: Allocated | AJ7: Direct | AK7: Source tags/labels | AL7: 1 | AM7: aws-2026-04-01-111111111111-03-02-alloc-749d93768ad9 | AN7: 46082 | AO7: 46082
A8: aws-2026-04-01-111111111111-04-01 | B8: AWS | C8: 999999999999 | D8: 111111111111 | E8: production-account | F8: 46112.833 | G8: 46113.833 | H8: 46112.833 | I8: 46142.833 | J8: AWS Lambda | K8: Compute | L8: Lambda-GB-Second | M8: function-1111-04-01 | N8: us-east-1 | P8: 4073882.4 | Q8: GB-Seconds | R8: 1.66667e-05 | S8: Standard | T8: USD | U8: 67.8982 | V8: 63.1452 | W8: 63.1452 | X8: Usage | Z8: Lambda-GB-Second | Invoke | Usage | AA8: {"application":"Checkout","cost_center":"CC-1001","environment":"production","team":"Payments"} | AB8: Checkout | AC8: production | AD8: CC-1001 | AE8: Payments | AF8: Allocated | AG8: aws_billing_sample.csv | AH8: 8 | AI8: Allocated | AJ8: Direct | AK8: Source tags/labels | AL8: 1 | AM8: aws-2026-04-01-111111111111-04-01-alloc-dcc914045cdc | AN8: 46082 | AO8: 46082
A9: aws-2026-04-01-111111111111-04-02 | B9: AWS | C9: 999999999999 | D9: 111111111111 | E9: production-account | F9: 46112.833 | G9: 46113.833 | H9: 46112.833 | I9: 46142.833 | J9: AWS Lambda | K9: Compute | L9: Lambda-GB-Second | M9: function-1111-04-02 | N9: us-east-1 | P9: 4634896 | Q9: GB-Seconds | R9: 1.66667e-05 | S9: Standard | T9: USD | U9: 77.2484 | V9: 71.8409 | W9: 71.8409 | X9: Usage | Z9: Lambda-GB-Second | Invoke | Usage | AA9: {"application":"Checkout","cost_center":"CC-1001","environment":"production","team":"Payments"} | AB9: Checkout | AC9: production | AD9: CC-1001 | AE9: Payments | AF9: Allocated | AG9: aws_billing_sample.csv | AH9: 9 | AI9: Allocated | AJ9: Direct | AK9: Source tags/labels | AL9: 1 | AM9: aws-2026-04-01-111111111111-04-02-alloc-a937b52190b9 | AN9: 46082 | AO9: 46082
A10: aws-2026-04-01-111111111111-05-01 | B10: AWS | C10: 999999999999 | D10: 111111111111 | E10: production-account | F10: 46112.833 | G10: 46113.833 | H10: 46112.833 | I10: 46142.833 | J10: AmazonCloudWatch | K10: Management and Governance | L10: DataProcessing-Bytes | M10: log-group-1111-05-01 | N10: us-east-1 | P10: 212.4198 | Q10: GB | R10: 0.5 | S10: Standard | T10: USD | U10: 106.2099 | V10: 97.7131 | W10: 97.7131 | X10: Usage | Z10: DataProcessing-Bytes | PutLogEvents | Usage | AA10: {"application":"Shared-Observability","cost_center":"CC-SHARED","environment":"production","team":"Platform"} | AB10: Checkout | AC10: production | AD10: CC-1001 | AE10: Payments | AF10: Allocated | AG10: aws_billing_sample.csv | AH10: 10 | AI10: Shared | AJ10: Shared-Proportional | AK10: Direct spend: provider + billing month + sub-account | AL10: 1 | AM10: aws-2026-04-01-111111111111-05-01-alloc-0c5fd9d9204d | AN10: 46082 | AO10: 46082
A11: aws-2026-04-01-111111111111-05-02 | B11: AWS | C11: 999999999999 | D11: 111111111111 | E11: production-account | F11: 46112.833 | G11: 46113.833 | H11: 46112.833 | I11: 46142.833 | J11: AmazonCloudWatch | K11: Management and Governance | L11: DataProcessing-Bytes | M11: log-group-1111-05-02 | N11: us-east-1 | P11: 238.9244 | Q11: GB | R11: 0.5 | S11: Standard | T11: USD | U11: 119.4622 | V11: 109.9052 | W11: 109.9052 | X11: Usage | Z11: DataProcessing-Bytes | PutLogEvents | Usage | AA11: {} | AB11: Unallocated | AC11: unknown | AD11: UNALLOCATED | AE11: Unassigned | AF11: Unallocated | AG11: aws_billing_sample.csv | AH11: 11 | AI11: Unallocated | AJ11: Unallocated | AK11: Missing allocation metadata | AL11: 1 | AM11: aws-2026-04-01-111111111111-05-02-alloc-1fe341e265b4 | AN11: 46082 | AO11: 46082
A12: aws-2026-04-01-222222222222-01-01 | B12: AWS | C12: 999999999999 | D12: 222222222222 | E12: development-account | F12: 46112.833 | G12: 46113.833 | H12: 46112.833 | I12: 46142.833 | J12: Amazon Elastic Compute Cloud - Compute | K12: Compute | L12: BoxUsage:m5.large | M12: i-2222-01-01 | N12: us-east-1 | P12: 445.6888 | Q12: Hrs | R12: 0.096 | S12: Standard | T12: USD | U12: 42.7861 | V12: 37.4379 | W12: 37.4379 | X12: Usage | Z12: BoxUsage:m5.large | RunInstances | Usage | AA12: {"application":"Analytics","cost_center":"CC-2001","environment":"development","team":"Data"} | AB12: Analytics | AC12: development | AD12: CC-2001 | AE12: Data | AF12: Allocated | AG12: aws_billing_sample.csv | AH12: 12 | AI12: Allocated | AJ12: Direct | AK12: Source tags/labels | AL12: 1 | AM12: aws-2026-04-01-222222222222-01-01-alloc-5f4c1c6c96d3 | AN12: 46082 | AO12: 46082
A13: aws-2026-04-01-222222222222-01-02 | B13: AWS | C13: 999999999999 | D13: 222222222222 | E13: development-account | F13: 46112.833 | G13: 46113.833 | H13: 46112.833 | I13: 46142.833 | J13: Amazon Elastic Compute Cloud - Compute | K13: Compute | L13: BoxUsage:m5.large | M13: i-2222-01-02 | N13: us-east-1 | P13: 406.581 | Q13: Hrs | R13: 0.096 | S13: Standard | T13: USD | U13: 39.0318 | V13: 34.1528 | W13: 34.1528 | X13: Usage | Z13: BoxUsage:m5.large | RunInstances | Usage | AA13: {"application":"Analytics","cost_center":"CC-2001","environment":"development","team":"Data"} | AB13: Analytics | AC13: development | AD13: CC-2001 | AE13: Data | AF13: Allocated | AG13: aws_billing_sample.csv | AH13: 13 | AI13: Allocated | AJ13: Direct | AK13: Source tags/labels | AL13: 1 | AM13: aws-2026-04-01-222222222222-01-02-alloc-b35afbec04ca | AN13: 46082 | AO13: 46082
... A1801: aws-2026-06-29-222222222222-05-02 | B1801: AWS | C1801: 999999999999 | D1801: 222222222222 | E1801: development-account | F1801: 46201.833 | G1801: 46202.833 | H1801: 46173.833 | I1801: 46203.833 | J1801: AmazonCloudWatch | K1801: Management and Governance | L1801: DataProcessing-Bytes | M1801: log-group-2222-05-02 | N1801: us-east-1 | P1801: 91.2078 | Q1801: GB | R1801: 0.5 | S1801: Standard | T1801: USD | U1801: 45.6039 | V1801: 41.9556 | W1801: 41.9556 | X1801: Usage | Z1801: DataProcessing-Bytes | PutLogEvents | Usage | AA1801: {"application":"Shared-Observability","cost_center":"CC-SHARED","environment":"development","team":"Platform"} | AB1801: Analytics | AC1801: development | AD1801: CC-2001 | AE1801: Data | AF1801: Allocated | AG1801: aws_billing_sample.csv | AH1801: 1801 | AI1801: Shared | AJ1801: Shared-Proportional | AK1801: Direct spend: provider + billing month + sub-account | AL1801: 1 | AM1801: aws-2026-06-29-222222222222-05-02-alloc-125695d432a7 | AN1801: 46174 | AO1801: 46174
A1802: aws-adjustment-credit-2026-06-29-111111111111 | B1802: AWS | C1802: 999999999999 | D1802: 111111111111 | E1802: production-account | F1802: 46201.833 | G1802: 46202.833 | H1802: 46173.833 | I1802: 46203.833 | J1802: AWS Promotional Credits | K1802: Other | L1802: Credit | M1802: not-applicable | N1802: global | P1802: 0 | R1802: 0 | T1802: USD | U1802: 0 | V1802: -5000 | W1802: -5000 | X1802: Credit | Z1802: Credit | BillingAdjustment | AA1802: {"application":"Shared","cost_center":"CC-CORPORATE","environment":"production","team":"Finance"} | AB1802: Checkout | AC1802: production | AD1802: CC-1001 | AE1802: Payments | AF1802: Allocated | AG1802: aws_billing_sample.csv | AH1802: 1802 | AI1802: Shared | AJ1802: Shared-Proportional | AK1802: Direct spend: provider + billing month + sub-account | AL1802: 1 | AM1802: aws-adjustment-credit-2026-06-29-111111111111-alloc-b331a9c13e00 | AN1802: 46174 | AO1802: 46174
A1803: aws-adjustment-refund-2026-05-20-222222222222 | B1803: AWS | C1803: 999999999999 | D1803: 222222222222 | E1803: development-account | F1803: 46161.833 | G1803: 46162.833 | H1803: 46142.833 | I1803: 46173.833 | J1803: Amazon Relational Database Service | K1803: Databases | L1803: Refund | M1803: not-applicable | N1803: global | P1803: 0 | R1803: 0 | S1803: Other | T1803: USD | U1803: 0 | V1803: -750 | W1803: -750 | X1803: Usage | Z1803: Refund | BillingAdjustment | AA1803: {"application":"Analytics","cost_center":"CC-2001","environment":"development","team":"Data"} | AB1803: Analytics | AC1803: development | AD1803: CC-2001 | AE1803: Data | AF1803: Allocated | AG1803: aws_billing_sample.csv | AH1803: 1803 | AI1803: Allocated | AJ1803: Direct | AK1803: Source tags/labels | AL1803: 1 | AM1803: aws-adjustment-refund-2026-05-20-222222222222-alloc-8fcd0b60ab3d | AN1803: 46143 | AO1803: 46143
A1804: aws-2026-04-01-222222222222-01-01 | B1804: AWS | C1804: 999999999999 | D1804: 222222222222 | E1804: development-account | F1804: 46112.833 | G1804: 46113.833 | H1804: 46112.833 | I1804: 46142.833 | J1804: Amazon Elastic Compute Cloud - Compute | K1804: Compute | L1804: BoxUsage:m5.large | M1804: i-2222-01-01 | N1804: us-east-1 | P1804: 445.6888 | Q1804: Hrs | R1804: 0.096 | S1804: Standard | T1804: USD | U1804: 42.7861 | V1804: 37.4379 | W1804: 37.4379 | X1804: Usage | Z1804: BoxUsage:m5.large | RunInstances | Usage | AA1804: {"application":"Analytics","cost_center":"CC-2001","environment":"development","team":"Data"} | AB1804: Analytics | AC1804: development | AD1804: CC-2001 | AE1804: Data | AF1804: Allocated | AG1804: aws_billing_sample.csv | AH1804: 1804 | AI1804: Allocated | AJ1804: Direct | AK1804: Source tags/labels | AL1804: 1 | AM1804: aws-2026-04-01-222222222222-01-01-alloc-5f4c1c6c96d3 | AN1804: 46082 | AO1804: 46082
A1805: aws-invalid-negative-usage-cost | B1805: AWS | C1805: 999999999999 | D1805: 111111111111 | E1805: production-account | F1805: 46113.833 | G1805: 46114.833 | H1805: 46112.833 | I1805: 46142.833 | J1805: Amazon Elastic Compute Cloud - Compute | K1805: Compute | L1805: BoxUsage:m5.large | M1805: i-1111-01-01 | N1805: us-east-1 | P1805: 1124.1875 | Q1805: Hrs | R1805: 0.096 | S1805: Standard | T1805: USD | U1805: 107.922 | V1805: -250 | W1805: -250 | X1805: Usage | Z1805: BoxUsage:m5.large | RunInstances | Usage | AA1805: {} | AB1805: Unallocated | AC1805: unknown | AD1805: UNALLOCATED | AE1805: Unassigned | AF1805: Unallocated | AG1805: aws_billing_sample.csv | AH1805: 1805 | AI1805: Unallocated | AJ1805: Unallocated | AK1805: Missing allocation metadata | AL1805: 1 | AM1805: aws-invalid-negative-usage-cost-alloc-e3d1459ace69 | AN1805: 46113 | AO1805: 46113
A1806: gcp-2026-04-01-finops-prod-1001-01-01 | B1806: GCP | E1806: customer-platform-prod | F1806: 46112.833 | G1806: 46113.833 | H1806: 46112.833 | I1806: 46142.833 | J1806: Compute Engine | K1806: Compute | L1806: N2 Instance Core running in Americas | M1806: instance-1001-01-01 | N1806: us-central1 | P1806: 1539.775 | Q1806: vCPU-hours | R1806: 0.031610982 | S1806: Committed | T1806: USD | U1806: 48.6738 | V1806: 39.4952 | W1806: 39.4952 | X1806: Usage | Z1806: N2 Instance Core running in Americas | AA1806: {"application":"storefront","cost_center":"cc-3001","environment":"production","team":"commerce"} | AB1806: storefront | AC1806: production | AD1806: cc-3001 | AE1806: commerce | AF1806: Allocated | AG1806: gcp_billing_sample.csv | AH1806: 2 | AI1806: Allocated | AJ1806: Direct | AK1806: Source tags/labels | AL1806: 1 | AM1806: gcp-2026-04-01-finops-prod-1001-01-01-alloc-c69424fa0e24 | AN1806: 46082 | AO1806: 46082
A1807: gcp-2026-04-01-finops-prod-1001-01-02 | B1807: GCP | E1807: customer-platform-prod | F1807: 46112.833 | G1807: 46113.833 | H1807: 46112.833 | I1807: 46142.833 | J1807: Compute Engine | K1807: Compute | L1807: N2 Instance Core running in Americas | M1807: instance-1001-01-02 | N1807: us-central1 | P1807: 1537.2503 | Q1807: vCPU-hours | R1807: 0.031610987 | S1807: Committed | T1807: USD | U1807: 48.594 | V1807: 39.4304 | W1807: 39.4304 | X1807: Usage | Z1807: N2 Instance Core running in Americas | AA1807: {"application":"storefront","cost_center":"cc-3001","environment":"production","team":"commerce"} | AB1807: storefront | AC1807: production | AD1807: cc-3001 | AE1807: commerce | AF1807: Allocated | AG1807: gcp_billing_sample.csv | AH1807: 3 | AI1807: Allocated | AJ1807: Direct | AK1807: Source tags/labels | AL1807: 1 | AM1807: gcp-2026-04-01-finops-prod-1001-01-02-alloc-5bc35529877e | AN1807: 46082 | AO1807: 46082
A1808: gcp-2026-04-01-finops-prod-1001-02-01 | B1808: GCP | E1808: customer-platform-prod | F1808: 46112.833 | G1808: 46113.833 | H1808: 46112.833 | I1808: 46142.833 | J1808: BigQuery | K1808: Analytics | L1808: Analysis in US | M1808: bq-job-1001-02-01 | N1808: us-central1 | P1808: 11.6287 | Q1808: TiBy | R1808: 6.2500021 | S1808: Standard | T1808: USD | U1808: 72.6794 | V1808: 69.0454 | W1808: 69.0454 | X1808: Usage | Z1808: Analysis in US | AA1808: {"application":"storefront","cost_center":"cc-3001","environment":"production","team":"commerce"} | AB1808: storefront | AC1808: production | AD1808: cc-3001 | AE1808: commerce | AF1808: Allocated | AG1808: gcp_billing_sample.csv | AH1808: 4 | AI1808: Allocated | AJ1808: Direct | AK1808: Source tags/labels | AL1808: 1 | AM1808: gcp-2026-04-01-finops-prod-1001-02-01-alloc-16de35a14a23 | AN1808: 46082 | AO1808: 46082
A1809: gcp-2026-04-01-finops-prod-1001-02-02 | B1809: GCP | E1809: customer-platform-prod | F1809: 46112.833 | G1809: 46113.833 | H1809: 46112.833 | I1809: 46142.833 | J1809: BigQuery | K1809: Analytics | L1809: Analysis in US | M1809: bq-job-1001-02-02 | N1809: us-central1 | P1809: 13.1552 | Q1809: TiBy | R1809: 6.25 | S1809: Standard | T1809: USD | U1809: 82.22 | V1809: 78.109 | W1809: 78.109 | X1809: Usage | Z1809: Analysis in US | AA1809: {"application":"storefront","cost_center":"cc-3001","environment":"production","team":"commerce"} | AB1809: storefront | AC1809: production | AD1809: cc-3001 | AE1809: commerce | AF1809: Allocated | AG1809: gcp_billing_sample.csv | AH1809: 5 | AI1809: Allocated | AJ1809: Direct | AK1809: Source tags/labels | AL1809: 1 | AM1809: gcp-2026-04-01-finops-prod-1001-02-02-alloc-357c105d7a6c | AN1809: 46082 | AO1809: 46082
A1810: gcp-2026-04-01-finops-prod-1001-03-01 | B1810: GCP | E1810: customer-platform-prod | F1810: 46112.833 | G1810: 46113.833 | H1810: 46112.833 | I1810: 46142.833 | J1810: Cloud Storage | K1810: Storage | L1810: Standard Storage US Multi-region | M1810: bucket-1001-03-01 | N1810: us-central1 | P1810: 349.3329 | Q1810: GiBy-month | R1810: 0.026000128 | S1810: Standard | T1810: USD | U1810: 9.0827 | V1810: 8.384 | W1810: 8.384 | X1810: Usage | Z1810: Standard Storage US Multi-region | AA1810: {"application":"storefront","cost_center":"cc-3001","environment":"production","team":"commerce"} | AB1810: storefront | AC1810: production | AD1810: cc-3001 | AE1810: commerce | AF1810: Allocated | AG1810: gcp_billing_sample.csv | AH1810: 6 | AI1810: Allocated | AJ1810: Direct | AK1810: Source tags/labels | AL1810: 1 | AM1810: gcp-2026-04-01-finops-prod-1001-03-01-alloc-7c343fee48d7 | AN1810: 46082 | AO1810: 46082
A1811: gcp-2026-04-01-finops-prod-1001-03-02 | B1811: GCP | E1811: customer-platform-prod | F1811: 46112.833 | G1811: 46113.833 | H1811: 46112.833 | I1811: 46142.833 | J1811: Cloud Storage | K1811: Storage | L1811: Standard Storage US Multi-region | M1811: bucket-1001-03-02 | N1811: us-central1 | P1811: 332.436 | Q1811: GiBy-month | R1811: 0.025999892 | S1811: Standard | T1811: USD | U1811: 8.6433 | V1811: 7.9785 | W1811: 7.9785 | X1811: Usage | Z1811: Standard Storage US Multi-region | AA1811: {"application":"storefront","cost_center":"cc-3001","environment":"production","team":"commerce"} | AB1811: storefront | AC1811: production | AD1811: cc-3001 | AE1811: commerce | AF1811: Allocated | AG1811: gcp_billing_sample.csv | AH1811: 7 | AI1811: Allocated | AJ1811: Direct | AK1811: Source tags/labels | AL1811: 1 | AM1811: gcp-2026-04-01-finops-prod-1001-03-02-alloc-d3d7ef7dd6a5 | AN1811: 46082 | AO1811: 46082
A1812: gcp-2026-04-01-finops-prod-1001-04-01 | B1812: GCP | E1812: customer-platform-prod | F1812: 46112.833 | G1812: 46113.833 | H1812: 46112.833 | I1812: 46142.833 | J1812: Cloud SQL | K1812: Databases | L1812: Cloud SQL for PostgreSQL: Regional vCPU | M1812: cloudsql-1001-04-01 | N1812: us-central1 | P1812: 387.694 | Q1812: vCPU-hours | R1812: 0.082599937 | S1812: Committed | T1812: USD | U1812: 32.0235 | V1812: 26.3943 | W1812: 26.3943 | X1812: Usage | Z1812: Cloud SQL for PostgreSQL: Regional vCPU | AA1812: {"application":"storefront","cost_center":"cc-3001","environment":"production","team":"commerce"} | AB1812: storefront | AC1812: production | AD1812: cc-3001 | AE1812: commerce | AF1812: Allocated | AG1812: gcp_billing_sample.csv | AH1812: 8 | AI1812: Allocated | AJ1812: Direct | AK1812: Source tags/labels | AL1812: 1 | AM1812: gcp-2026-04-01-finops-prod-1001-04-01-alloc-0abc1b4e9cec | AN1812: 46082 | AO1812: 46082
A1813: gcp-2026-04-01-finops-prod-1001-04-02 | B1813: GCP | E1813: customer-platform-prod | F1813: 46112.833 | G1813: 46113.833 | H1813: 46112.833 | I1813: 46142.833 | J1813: Cloud SQL | K1813: Databases | L1813: Cloud SQL for PostgreSQL: Regional vCPU | M1813: cloudsql-1001-04-02 | N1813: us-central1 | P1813: 418.3511 | Q1813: vCPU-hours | R1813: 0.082599998 | S1813: Committed | T1813: USD | U1813: 34.5558 | V1813: 28.4814 | W1813: 28.4814 | X1813: Usage | Z1813: Cloud SQL for PostgreSQL: Regional vCPU | AA1813: {"application":"storefront","cost_center":"cc-3001","environment":"production","team":"commerce"} | AB1813: storefront | AC1813: production | AD1813: cc-3001 | AE1813: commerce | AF1813: Allocated | AG1813: gcp_billing_sample.csv | AH1813: 9 | AI1813: Allocated | AJ1813: Direct | AK1813: Source tags/labels | AL1813: 1 | AM1813: gcp-2026-04-01-finops-prod-1001-04-02-alloc-378a837f3d59 | AN1813: 46082 | AO1813: 46082
A1814: gcp-2026-04-01-finops-prod-1001-05-01 | B1814: GCP | E1814: customer-platform-prod | F1814: 46112.833 | G1814: 46113.833 | H1814: 46112.833 | I1814: 46142.833 | J1814: Cloud Logging | K1814: Management and Governance | L1814: Log Storage | M1814: log-sink-1001-05-01 | N1814: us-central1 | P1814: 310.0294 | Q1814: GiBy | R1814: 0.5 | S1814: Standard | T1814: USD | U1814: 155.0147 | V1814: 142.6135 | W1814: 142.6135 | X1814: Usage | Z1814: Log Storage | AA1814: {"application":"shared-logging","cost_center":"cc-shared","environment":"production","team":"platform"} | AB1814: storefront | AC1814: production | AD1814: cc-3001 | AE1814: commerce | AF1814: Allocated | AG1814: gcp_billing_sample.csv | AH1814: 10 | AI1814: Shared | AJ1814: Shared-Proportional | AK1814: Direct spend: provider + billing month + sub-account | AL1814: 1 | AM1814: gcp-2026-04-01-finops-prod-1001-05-01-alloc-745eb6a9f6b0 | AN1814: 46082 | AO1814: 46082
A1815: gcp-2026-04-01-finops-prod-1001-05-02 | B1815: GCP | E1815: customer-platform-prod | F1815: 46112.833 | G1815: 46113.833 | H1815: 46112.833 | I1815: 46142.833 | J1815: Cloud Logging | K1815: Management and Governance | L1815: Log Storage | M1815: log-sink-1001-05-02 | N1815: us-central1 | P1815: 314.8721 | Q1815: GiBy | R1815: 0.50000016 | S1815: Standard | T1815: USD | U1815: 157.4361 | V1815: 144.8412 | W1815: 144.8412 | X1815: Usage | Z1815: Log Storage | AA1815: {"application":"shared-logging","cost_center":"cc-shared","environment":"production","team":"platform"} | AB1815: storefront | AC1815: production | AD1815: cc-3001 | AE1815: commerce | AF1815: Allocated | AG1815: gcp_billing_sample.csv | AH1815: 11 | AI1815: Shared | AJ1815: Shared-Proportional | AK1815: Direct spend: provider + billing month + sub-account | AL1815: 1 | AM1815: gcp-2026-04-01-finops-prod-1001-05-02-alloc-28fc5000ac34 | AN1815: 46082 | AO1815: 46082
A1816: gcp-2026-04-01-finops-data-2001-01-01 | B1816: GCP | E1816: analytics-development | F1816: 46112.833 | G1816: 46113.833 | H1816: 46112.833 | I1816: 46142.833 | J1816: Compute Engine | K1816: Compute | L1816: N2 Instance Core running in Americas | M1816: instance-2001-01-01 | N1816: us-central1 | P1816: 646.1003 | Q1816: vCPU-hours | R1816: 0.031611036 | S1816: Committed | T1816: USD | U1816: 20.4239 | V1816: 16.5725 | W1816: 16.5725 | X1816: Usage | Z1816: N2 Instance Core running in Americas | AA1816: {"application":"lakehouse","cost_center":"cc-4001","environment":"development","team":"data"} | AB1816: lakehouse | AC1816: development | AD1816: cc-4001 | AE1816: data | AF1816: Allocated | AG1816: gcp_billing_sample.csv | AH1816: 12 | AI1816: Allocated | AJ1816: Direct | AK1816: Source tags/labels | AL1816: 1 | AM1816: gcp-2026-04-01-finops-data-2001-01-01-alloc-46f1d27d4d95 | AN1816: 46082 | AO1816: 46082
A1817: gcp-2026-04-01-finops-data-2001-01-02 | B1817: GCP | E1817: analytics-development | F1817: 46112.833 | G1817: 46113.833 | H1817: 46112.833 | I1817: 46142.833 | J1817: Compute Engine | K1817: Compute | L1817: N2 Instance Core running in Americas | M1817: instance-2001-01-02 | N1817: us-central1 | P1817: 716.6211 | Q1817: vCPU-hours | R1817: 0.031610987 | S1817: Committed | T1817: USD | U1817: 22.6531 | V1817: 18.3813 | W1817: 18.3813 | X1817: Usage | Z1817: N2 Instance Core running in Americas | AA1817: {"application":"lakehouse","cost_center":"cc-4001","environment":"development","team":"data"} | AB1817: lakehouse | AC1817: development | AD1817: cc-4001 | AE1817: data | AF1817: Allocated | AG1817: gcp_billing_sample.csv | AH1817: 13 | AI1817: Allocated | AJ1817: Direct | AK1817: Source tags/labels | AL1817: 1 | AM1817: gcp-2026-04-01-finops-data-2001-01-02-alloc-c00a321ed24f | AN1817: 46082 | AO1817: 46082
... A3605: gcp-2026-06-29-finops-data-2001-05-02 | B3605: GCP | E3605: analytics-development | F3605: 46201.833 | G3605: 46202.833 | H3605: 46173.833 | I3605: 46203.833 | J3605: Cloud Logging | K3605: Management and Governance | L3605: Log Storage | M3605: log-sink-2001-05-02 | N3605: us-central1 | P3605: 133.163 | Q3605: GiBy | R3605: 0.5 | S3605: Standard | T3605: USD | U3605: 66.5815 | V3605: 61.255 | W3605: 61.255 | X3605: Usage | Z3605: Log Storage | AA3605: {"application":"shared-logging","cost_center":"cc-shared","environment":"development","team":"platform"} | AB3605: lakehouse | AC3605: development | AD3605: cc-4001 | AE3605: data | AF3605: Allocated | AG3605: gcp_billing_sample.csv | AH3605: 1801 | AI3605: Shared | AJ3605: Shared-Proportional | AK3605: Direct spend: provider + billing month + sub-account | AL3605: 1 | AM3605: gcp-2026-06-29-finops-data-2001-05-02-alloc-468a4fa28265 | AN3605: 46174 | AO3605: 46174
A3606: gcp-adjustment-regular-2026-06-29-finops-prod-1001 | B3606: GCP | E3606: customer-platform-prod | F3606: 46201.833 | G3606: 46202.833 | H3606: 46173.833 | I3606: 46203.833 | J3606: Promotional Credits | K3606: Other | L3606: Free Trial Credit | M3606: not-applicable | N3606: global | P3606: 0 | R3606: Unallocated | T3606: USD | U3606: 0 | V3606: -4500 | W3606: -4500 | X3606: Credit | Z3606: Free Trial Credit | AA3606: {"application":"shared","cost_center":"cc-corporate","environment":"production","team":"finance"} | AB3606: storefront | AC3606: production | AD3606: cc-3001 | AE3606: commerce | AF3606: Allocated | AG3606: gcp_billing_sample.csv | AH3606: 1802 | AI3606: Shared | AJ3606: Shared-Proportional | AK3606: Direct spend: provider + billing month + sub-account | AL3606: 1 | AM3606: gcp-adjustment-regular-2026-06-29-finops-prod-1001-alloc-d9db30949e16 | AN3606: 46174 | AO3606: 46174
A3607: gcp-adjustment-adjustment-2026-05-18-finops-data-2001 | B3607: GCP | E3607: analytics-development | F3607: 46159.833 | G3607: 46160.833 | H3607: 46142.833 | I3607: 46173.833 | J3607: Cloud SQL | K3607: Databases | L3607: Billing Adjustment Refund | M3607: not-applicable | N3607: global | P3607: 0 | R3607: Unallocated | T3607: USD | U3607: 0 | V3607: -600 | W3607: -600 | X3607: Adjustment | Z3607: Billing Adjustment Refund | AA3607: {"application":"lakehouse","cost_center":"cc-4001","environment":"development","team":"data"} | AB3607: lakehouse | AC3607: development | AD3607: cc-4001 | AE3607: data | AF3607: Allocated | AG3607: gcp_billing_sample.csv | AH3607: 1803 | AI3607: Allocated | AJ3607: Direct | AK3607: Source tags/labels | AL3607: 1 | AM3607: gcp-adjustment-adjustment-2026-05-18-finops-data-2001-alloc-3c927090a68c | AN3607: 46143 | AO3607: 46143
A3608: gcp-2026-04-01-finops-data-2001-03-02 | B3608: GCP | E3608: analytics-development | F3608: 46112.833 | G3608: 46113.833 | H3608: 46112.833 | I3608: 46142.833 | J3608: Cloud Storage | K3608: Storage | L3608: Standard Storage US Multi-region | M3608: bucket-2001-03-02 | N3608: us-central1 | P3608: 137.8545 | Q3608: GiBy-month | R3608: 0.025999877 | S3608: Standard | T3608: USD | U3608: 3.5842 | V3608: 3.3085 | W3608: 3.3085 | X3608: Usage | Z3608: Standard Storage US Multi-region | AA3608: {"application":"lakehouse","cost_center":"cc-4001","environment":"development","team":"data"} | AB3608: lakehouse | AC3608: development | AD3608: cc-4001 | AE3608: data | AF3608: Allocated | AG3608: gcp_billing_sample.csv | AH3608: 1804 | AI3608: Allocated | AJ3608: Direct | AK3608: Source tags/labels | AL3608: 1 | AM3608: gcp-2026-04-01-finops-data-2001-03-02-alloc-32623d441e04 | AN3608: 46082 | AO3608: 46082
A3609: gcp-invalid-negative-regular-cost | B3609: GCP | E3609: customer-platform-prod | F3609: 46113.833 | G3609: 46114.833 | H3609: 46112.833 | I3609: 46142.833 | J3609: Cloud Storage | K3609: Storage | L3609: Standard Storage US Multi-region | M3609: bucket-1001-03-02 | N3609: us-central1 | P3609: 312.8035 | Q3609: GiBy-month | R3609: 0.026000029 | S3609: Standard | T3609: USD | U3609: 8.1329 | V3609: -300 | W3609: -300 | X3609: Usage | Z3609: Standard Storage US Multi-region | AA3609: {"application":"storefront","cost_center":"cc-3001","environment":"production","team":"commerce"} | AB3609: storefront | AC3609: production | AD3609: cc-3001 | AE3609: commerce | AF3609: Allocated | AG3609: gcp_billing_sample.csv | AH3609: 1805 | AI3609: Allocated | AJ3609: Direct | AK3609: Source tags/labels | AL3609: 1 | AM3609: gcp-invalid-negative-regular-cost-alloc-d7cb38992fe1 | AN3609: 46113 | AO3609: 46113

Sheet Scenarios
A1: scenario | B1: scenario_description | C1: forecast_multiplier | D1: optimization_savings_pct | E1: scenario_forecast | F1: approved_budget | G1: variance_to_budget | H1: variance_pct | I1: change_vs_base | J1: status
A2: Base | B2: Current blended month-end forecast | C2: 1 | D2: 0 | E2: =SUM(Forecast_Query[blended_forecast]) -> 42687.034 | F2: =SUM(Forecast_Query[approved_budget]) -> 54751.018 | G2: =E2-F2 -> -12063.985 | H2: =IF(F2=0,"",G2/ABS(F2)) -> -0.22034266 | I2: =0 -> 0 | J2: =IF(F2=0,"No Budget",IF(G2>0,"Over Budget",IF(G2<0,"Within Budget","On Budget"))) -> Within Budget
A3: High Growth | B3: Forecast assuming 15% higher demand | C3: 1.15 | D3: 0 | E3: =$E$2*C3 -> 49090.089 | F3: =$F$2 -> 54751.018 | G3: =E3-F3 -> -5660.9298 | H3: =IF(F3=0,"",G3/ABS(F3)) -> -0.10339405 | I3: =E3-$E$2 -> 6403.055 | J3: =IF(F3=0,"No Budget",IF(G3>0,"Over Budget",IF(G3<0,"Within Budget","On Budget"))) -> Within Budget
A4: Optimization | B4: Forecast after 10% optimization savings | C4: 1 | D4: 0.1 | E4: =$E$2*(1-D4) -> 38418.33 | F4: =$F$2 -> 54751.018 | G4: =E4-F4 -> -16332.688 | H4: =IF(F4=0,"",G4/ABS(F4)) -> -0.29830839 | I4: =E4-$E$2 -> -4268.7034 | J4: =IF(F4=0,"No Budget",IF(G4>0,"Over Budget",IF(G4<0,"Within Budget","On Budget"))) -> Within Budget
A7: Base: Where current trends indicate spending will finish.
A8: High Growth: Cost exposure if workload demand is 15% higher.
A9: Optimization: Potential result if the organization reduces forecasted cost by 10%.

Sheet Budget_Input_Query
A1: billing_month | B1: provider_name | C1: application | D1: budget_key | E1: baseline_actual | F1: growth_rate | G1: months_from_baseline | H1: calculated_budget | I1: approved_budget | J1: budget_version | K1: budget_source | L1: comments
A2: 46113 | B2: AWS | C2: Analytics | D2: 202604|AWS|Analytics | E2: =SUMIFS(tblMonthly[actual_cost],tblMonthly[billing_month],Assumptions!$B$15,tblMonthly[provider_name],B2,tblMonthly[application],C2) -> 6676.5578 | F2: =_xlfn.XLOOKUP(B2,Assumptions!$F$5:$F$6,Assumptions!$G$5:$G$6,Assumptions!$B$16) -> 0.04 | G2: =12*(YEAR(tblBudget[[#This Row],[billing_month]])-YEAR(Assumptions!$B$15)) +MONTH(tblBudget[[#This Row],[billing_month]]) -MONTH(Assumptions!$B$15) -> 0 | H2: =E2*(1+F2)^G2 -> 6676.5578 | I2: =tblBudget[[#This Row],[calculated_budget]] -> 6676.5578 | J2: FY26 Synthetic Plan v1 | K2: April Baseline + Provider Growth
A3: 46113 | B3: AWS | C3: Checkout | D3: 202604|AWS|Checkout | E3: =SUMIFS(tblMonthly[actual_cost],tblMonthly[billing_month],Assumptions!$B$15,tblMonthly[provider_name],B3,tblMonthly[application],C3) -> 17008.158 | F3: =_xlfn.XLOOKUP(B3,Assumptions!$F$5:$F$6,Assumptions!$G$5:$G$6,Assumptions!$B$16) -> 0.04 | G3: =12*(YEAR(tblBudget[[#This Row],[billing_month]])-YEAR(Assumptions!$B$15)) +MONTH(tblBudget[[#This Row],[billing_month]]) -MONTH(Assumptions!$B$15) -> 0 | H3: =E3*(1+F3)^G3 -> 17008.158 | I3: =tblBudget[[#This Row],[calculated_budget]] -> 17008.158 | J3: FY26 Synthetic Plan v1 | K3: April Baseline + Provider Growth
A4: 46113 | B4: AWS | C4: Unallocated | D4: 202604|AWS|Unallocated | E4: =SUMIFS(tblMonthly[actual_cost],tblMonthly[billing_month],Assumptions!$B$15,tblMonthly[provider_name],B4,tblMonthly[application],C4) -> 1613.8527 | F4: =_xlfn.XLOOKUP(B4,Assumptions!$F$5:$F$6,Assumptions!$G$5:$G$6,Assumptions!$B$16) -> 0.04 | G4: =12*(YEAR(tblBudget[[#This Row],[billing_month]])-YEAR(Assumptions!$B$15)) +MONTH(tblBudget[[#This Row],[billing_month]]) -MONTH(Assumptions!$B$15) -> 0 | H4: =E4*(1+F4)^G4 -> 1613.8527 | I4: =tblBudget[[#This Row],[calculated_budget]] -> 1613.8527 | J4: FY26 Synthetic Plan v1 | K4: April Baseline + Provider Growth
A5: 46113 | B5: GCP | C5: Unallocated | D5: 202604|GCP|Unallocated | E5: =SUMIFS(tblMonthly[actual_cost],tblMonthly[billing_month],Assumptions!$B$15,tblMonthly[provider_name],B5,tblMonthly[application],C5) -> 2118.3359 | F5: =_xlfn.XLOOKUP(B5,Assumptions!$F$5:$F$6,Assumptions!$G$5:$G$6,Assumptions!$B$16) -> 0.06 | G5: =12*(YEAR(tblBudget[[#This Row],[billing_month]])-YEAR(Assumptions!$B$15)) +MONTH(tblBudget[[#This Row],[billing_month]]) -MONTH(Assumptions!$B$15) -> 0 | H5: =E5*(1+F5)^G5 -> 2118.3359 | I5: =tblBudget[[#This Row],[calculated_budget]] -> 2118.3359 | J5: FY26 Synthetic Plan v1 | K5: April Baseline + Provider Growth
A6: 46113 | B6: GCP | C6: lakehouse | D6: 202604|GCP|lakehouse | E6: =SUMIFS(tblMonthly[actual_cost],tblMonthly[billing_month],Assumptions!$B$15,tblMonthly[provider_name],B6,tblMonthly[application],C6) -> 6922.86 | F6: =_xlfn.XLOOKUP(B6,Assumptions!$F$5:$F$6,Assumptions!$G$5:$G$6,Assumptions!$B$16) -> 0.06 | G6: =12*(YEAR(tblBudget[[#This Row],[billing_month]])-YEAR(Assumptions!$B$15)) +MONTH(tblBudget[[#This Row],[billing_month]]) -MONTH(Assumptions!$B$15) -> 0 | H6: =E6*(1+F6)^G6 -> 6922.86 | I6: =tblBudget[[#This Row],[calculated_budget]] -> 6922.86 | J6: FY26 Synthetic Plan v1 | K6: April Baseline + Provider Growth
A7: 46113 | B7: GCP | C7: storefront | D7: 202604|GCP|storefront | E7: =SUMIFS(tblMonthly[actual_cost],tblMonthly[billing_month],Assumptions!$B$15,tblMonthly[provider_name],B7,tblMonthly[application],C7) -> 15334.104 | F7: =_xlfn.XLOOKUP(B7,Assumptions!$F$5:$F$6,Assumptions!$G$5:$G$6,Assumptions!$B$16) -> 0.06 | G7: =12*(YEAR(tblBudget[[#This Row],[billing_month]])-YEAR(Assumptions!$B$15)) +MONTH(tblBudget[[#This Row],[billing_month]]) -MONTH(Assumptions!$B$15) -> 0 | H7: =E7*(1+F7)^G7 -> 15334.104 | I7: =tblBudget[[#This Row],[calculated_budget]] -> 15334.104 | J7: FY26 Synthetic Plan v1 | K7: April Baseline + Provider Growth
A8: 46143 | B8: AWS | C8: Analytics | D8: 202605|AWS|Analytics | E8: =SUMIFS(tblMonthly[actual_cost],tblMonthly[billing_month],Assumptions!$B$15,tblMonthly[provider_name],B8,tblMonthly[application],C8) -> 6676.5578 | F8: =_xlfn.XLOOKUP(B8,Assumptions!$F$5:$F$6,Assumptions!$G$5:$G$6,Assumptions!$B$16) -> 0.04 | G8: =12*(YEAR(tblBudget[[#This Row],[billing_month]])-YEAR(Assumptions!$B$15)) +MONTH(tblBudget[[#This Row],[billing_month]]) -MONTH(Assumptions!$B$15) -> 1 | H8: =E8*(1+F8)^G8 -> 6943.6201 | I8: =tblBudget[[#This Row],[calculated_budget]] -> 6943.6201 | J8: FY26 Synthetic Plan v1 | K8: April Baseline + Provider Growth
A9: 46143 | B9: AWS | C9: Checkout | D9: 202605|AWS|Checkout | E9: =SUMIFS(tblMonthly[actual_cost],tblMonthly[billing_month],Assumptions!$B$15,tblMonthly[provider_name],B9,tblMonthly[application],C9) -> 17008.158 | F9: =_xlfn.XLOOKUP(B9,Assumptions!$F$5:$F$6,Assumptions!$G$5:$G$6,Assumptions!$B$16) -> 0.04 | G9: =12*(YEAR(tblBudget[[#This Row],[billing_month]])-YEAR(Assumptions!$B$15)) +MONTH(tblBudget[[#This Row],[billing_month]]) -MONTH(Assumptions!$B$15) -> 1 | H9: =E9*(1+F9)^G9 -> 17688.484 | I9: =tblBudget[[#This Row],[calculated_budget]] -> 17688.484 | J9: FY26 Synthetic Plan v1 | K9: April Baseline + Provider Growth
A10: 46143 | B10: AWS | C10: Unallocated | D10: 202605|AWS|Unallocated | E10: =SUMIFS(tblMonthly[actual_cost],tblMonthly[billing_month],Assumptions!$B$15,tblMonthly[provider_name],B10,tblMonthly[application],C10) -> 1613.8527 | F10: =_xlfn.XLOOKUP(B10,Assumptions!$F$5:$F$6,Assumptions!$G$5:$G$6,Assumptions!$B$16) -> 0.04 | G10: =12*(YEAR(tblBudget[[#This Row],[billing_month]])-YEAR(Assumptions!$B$15)) +MONTH(tblBudget[[#This Row],[billing_month]]) -MONTH(Assumptions!$B$15) -> 1 | H10: =E10*(1+F10)^G10 -> 1678.4068 | I10: =tblBudget[[#This Row],[calculated_budget]] -> 1678.4068 | J10: FY26 Synthetic Plan v1 | K10: April Baseline + Provider Growth
A11: 46143 | B11: GCP | C11: Unallocated | D11: 202605|GCP|Unallocated | E11: =SUMIFS(tblMonthly[actual_cost],tblMonthly[billing_month],Assumptions!$B$15,tblMonthly[provider_name],B11,tblMonthly[application],C11) -> 2118.3359 | F11: =_xlfn.XLOOKUP(B11,Assumptions!$F$5:$F$6,Assumptions!$G$5:$G$6,Assumptions!$B$16) -> 0.06 | G11: =12*(YEAR(tblBudget[[#This Row],[billing_month]])-YEAR(Assumptions!$B$15)) +MONTH(tblBudget[[#This Row],[billing_month]]) -MONTH(Assumptions!$B$15) -> 1 | H11: =E11*(1+F11)^G11 -> 2245.4361 | I11: =tblBudget[[#This Row],[calculated_budget]] -> 2245.4361 | J11: FY26 Synthetic Plan v1 | K11: April Baseline + Provider Growth
A12: 46143 | B12: GCP | C12: lakehouse | D12: 202605|GCP|lakehouse | E12: =SUMIFS(tblMonthly[actual_cost],tblMonthly[billing_month],Assumptions!$B$15,tblMonthly[provider_name],B12,tblMonthly[application],C12) -> 6922.86 | F12: =_xlfn.XLOOKUP(B12,Assumptions!$F$5:$F$6,Assumptions!$G$5:$G$6,Assumptions!$B$16) -> 0.06 | G12: =12*(YEAR(tblBudget[[#This Row],[billing_month]])-YEAR(Assumptions!$B$15)) +MONTH(tblBudget[[#This Row],[billing_month]]) -MONTH(Assumptions!$B$15) -> 1 | H12: =E12*(1+F12)^G12 -> 7338.2316 | I12: =tblBudget[[#This Row],[calculated_budget]] -> 7338.2316 | J12: FY26 Synthetic Plan v1 | K12: April Baseline + Provider Growth
A13: 46143 | B13: GCP | C13: storefront | D13: 202605|GCP|storefront | E13: =SUMIFS(tblMonthly[actual_cost],tblMonthly[billing_month],Assumptions!$B$15,tblMonthly[provider_name],B13,tblMonthly[application],C13) -> 15334.104 | F13: =_xlfn.XLOOKUP(B13,Assumptions!$F$5:$F$6,Assumptions!$G$5:$G$6,Assumptions!$B$16) -> 0.06 | G13: =12*(YEAR(tblBudget[[#This Row],[billing_month]])-YEAR(Assumptions!$B$15)) +MONTH(tblBudget[[#This Row],[billing_month]]) -MONTH(Assumptions!$B$15) -> 1 | H13: =E13*(1+F13)^G13 -> 16254.15 | I13: =tblBudget[[#This Row],[calculated_budget]] -> 16254.15 | J13: FY26 Synthetic Plan v1 | K13: April Baseline + Provider Growth
... A19: 46174 | B19: GCP | C19: storefront | D19: 202606|GCP|storefront | E19: =SUMIFS(tblMonthly[actual_cost],tblMonthly[billing_month],Assumptions!$B$15,tblMonthly[provider_name],B19,tblMonthly[application],C19) -> 15334.104 | F19: =_xlfn.XLOOKUP(B19,Assumptions!$F$5:$F$6,Assumptions!$G$5:$G$6,Assumptions!$B$16) -> 0.06 | G19: =12*(YEAR(tblBudget[[#This Row],[billing_month]])-YEAR(Assumptions!$B$15)) +MONTH(tblBudget[[#This Row],[billing_month]]) -MONTH(Assumptions!$B$15) -> 2 | H19: =E19*(1+F19)^G19 -> 17229.399 | I19: =tblBudget[[#This Row],[calculated_budget]] -> 17229.399 | J19: FY26 Synthetic Plan v1 | K19: April Baseline + Provider Growth

Sheet Variance_Drivers
A1: billing_month | B1: provider_name | C1: application | D1: service_name | E1: sku_description | F1: consumed_unit | G1: current_quantity | H1: current_cost | I1: prior_quantity | J1: prior_cost | K1: current_rate | L1: prior_rate | M1: usage_effect | N1: rate_effect | O1: scope_effect | P1: total_cost_change | Q1: decomposition_check | R1: primary_driver
A2: 46082 | B2: AWS | C2: Unallocated | D2: Amazon Elastic Compute Cloud - Compute | E2: BoxUsage:m5.large | F2: Hrs | G2: 1110.1162 | H2: 93.2498 | I2: =SUMIFS(tblDrivers[current_quantity],tblDrivers[billing_month],EDATE(A2,-1),tblDrivers[provider_name],B2,tblDrivers[application],C2,tblDrivers[service_name],D2,tblDrivers[sku_description],E2,tblDrivers[consumed_unit],F2) -> 0 | J2: =SUMIFS(tblDrivers[current_cost],tblDrivers[billing_month],EDATE(A2,-1),tblDrivers[provider_name],B2,tblDrivers[application],C2,tblDrivers[service_name],D2,tblDrivers[sku_description],E2,tblDrivers[consumed_unit],F2) -> 0 | K2: =IFERROR(H2/G2,0) -> 0.084000035 | L2: =IFERROR(J2/I2,0) -> 0 | M2: =IF(I2=0,0,(G2-I2)*L2) -> 0 | N2: =IF(I2=0,0,G2*(K2-L2)) -> 0 | O2: =IF(AND(I2=0,G2>0),H2,0) -> 93.2498 | P2: =H2-J2 -> 93.2498 | Q2: =P2-(M2+N2+O2) -> 0 | R2: =IF(O2<>0,"Scope",IF(ABS(M2)>=ABS(N2),"Usage","Rate")) -> Scope
A3: 46082 | B3: AWS | C3: Checkout | D3: Amazon Elastic Compute Cloud - Compute | E3: BoxUsage:m5.large | F3: Hrs | G3: 1031.4063 | H3: 86.6381 | I3: =SUMIFS(tblDrivers[current_quantity],tblDrivers[billing_month],EDATE(A3,-1),tblDrivers[provider_name],B3,tblDrivers[application],C3,tblDrivers[service_name],D3,tblDrivers[sku_description],E3,tblDrivers[consumed_unit],F3) -> 0 | J3: =SUMIFS(tblDrivers[current_cost],tblDrivers[billing_month],EDATE(A3,-1),tblDrivers[provider_name],B3,tblDrivers[application],C3,tblDrivers[service_name],D3,tblDrivers[sku_description],E3,tblDrivers[consumed_unit],F3) -> 0 | K3: =IFERROR(H3/G3,0) -> 0.083999972 | L3: =IFERROR(J3/I3,0) -> 0 | M3: =IF(I3=0,0,(G3-I3)*L3) -> 0 | N3: =IF(I3=0,0,G3*(K3-L3)) -> 0 | O3: =IF(AND(I3=0,G3>0),H3,0) -> 86.6381 | P3: =H3-J3 -> 86.6381 | Q3: =P3-(M3+N3+O3) -> 0 | R3: =IF(O3<>0,"Scope",IF(ABS(M3)>=ABS(N3),"Usage","Rate")) -> Scope
A4: 46082 | B4: AWS | C4: Checkout | D4: Amazon Simple Storage Service | E4: TimedStorage-ByteHrs | F4: GB-Mo | G4: 497.4209 | H4: 10.6945 | I4: =SUMIFS(tblDrivers[current_quantity],tblDrivers[billing_month],EDATE(A4,-1),tblDrivers[provider_name],B4,tblDrivers[application],C4,tblDrivers[service_name],D4,tblDrivers[sku_description],E4,tblDrivers[consumed_unit],F4) -> 0 | J4: =SUMIFS(tblDrivers[current_cost],tblDrivers[billing_month],EDATE(A4,-1),tblDrivers[provider_name],B4,tblDrivers[application],C4,tblDrivers[service_name],D4,tblDrivers[sku_description],E4,tblDrivers[consumed_unit],F4) -> 0 | K4: =IFERROR(H4/G4,0) -> 0.021499901 | L4: =IFERROR(J4/I4,0) -> 0 | M4: =IF(I4=0,0,(G4-I4)*L4) -> 0 | N4: =IF(I4=0,0,G4*(K4-L4)) -> 0 | O4: =IF(AND(I4=0,G4>0),H4,0) -> 10.6945 | P4: =H4-J4 -> 10.6945 | Q4: =P4-(M4+N4+O4) -> 0 | R4: =IF(O4<>0,"Scope",IF(ABS(M4)>=ABS(N4),"Usage","Rate")) -> Scope
A5: 46082 | B5: AWS | C5: Unallocated | D5: Amazon Relational Database Service | E5: InstanceUsage:db.m5.large | F5: Hrs | G5: 212.627 | H5: 36.1466 | I5: =SUMIFS(tblDrivers[current_quantity],tblDrivers[billing_month],EDATE(A5,-1),tblDrivers[provider_name],B5,tblDrivers[application],C5,tblDrivers[service_name],D5,tblDrivers[sku_description],E5,tblDrivers[consumed_unit],F5) -> 0 | J5: =SUMIFS(tblDrivers[current_cost],tblDrivers[billing_month],EDATE(A5,-1),tblDrivers[provider_name],B5,tblDrivers[application],C5,tblDrivers[service_name],D5,tblDrivers[sku_description],E5,tblDrivers[consumed_unit],F5) -> 0 | K5: =IFERROR(H5/G5,0) -> 0.17000005 | L5: =IFERROR(J5/I5,0) -> 0 | M5: =IF(I5=0,0,(G5-I5)*L5) -> 0 | N5: =IF(I5=0,0,G5*(K5-L5)) -> 0 | O5: =IF(AND(I5=0,G5>0),H5,0) -> 36.1466 | P5: =H5-J5 -> 36.1466 | Q5: =P5-(M5+N5+O5) -> 0 | R5: =IF(O5<>0,"Scope",IF(ABS(M5)>=ABS(N5),"Usage","Rate")) -> Scope
A6: 46082 | B6: AWS | C6: Checkout | D6: Amazon Relational Database Service | E6: InstanceUsage:db.m5.large | F6: Hrs | G6: 203.8452 | H6: 34.6537 | I6: =SUMIFS(tblDrivers[current_quantity],tblDrivers[billing_month],EDATE(A6,-1),tblDrivers[provider_name],B6,tblDrivers[application],C6,tblDrivers[service_name],D6,tblDrivers[sku_description],E6,tblDrivers[consumed_unit],F6) -> 0 | J6: =SUMIFS(tblDrivers[current_cost],tblDrivers[billing_month],EDATE(A6,-1),tblDrivers[provider_name],B6,tblDrivers[application],C6,tblDrivers[service_name],D6,tblDrivers[sku_description],E6,tblDrivers[consumed_unit],F6) -> 0 | K6: =IFERROR(H6/G6,0) -> 0.17000008 | L6: =IFERROR(J6/I6,0) -> 0 | M6: =IF(I6=0,0,(G6-I6)*L6) -> 0 | N6: =IF(I6=0,0,G6*(K6-L6)) -> 0 | O6: =IF(AND(I6=0,G6>0),H6,0) -> 34.6537 | P6: =H6-J6 -> 34.6537 | Q6: =P6-(M6+N6+O6) -> 0 | R6: =IF(O6<>0,"Scope",IF(ABS(M6)>=ABS(N6),"Usage","Rate")) -> Scope
A7: 46082 | B7: AWS | C7: Checkout | D7: AWS Lambda | E7: Lambda-GB-Second | F7: GB-Seconds | G7: 8708778.4 | H7: 134.9861 | I7: =SUMIFS(tblDrivers[current_quantity],tblDrivers[billing_month],EDATE(A7,-1),tblDrivers[provider_name],B7,tblDrivers[application],C7,tblDrivers[service_name],D7,tblDrivers[sku_description],E7,tblDrivers[consumed_unit],F7) -> 0 | J7: =SUMIFS(tblDrivers[current_cost],tblDrivers[billing_month],EDATE(A7,-1),tblDrivers[provider_name],B7,tblDrivers[application],C7,tblDrivers[service_name],D7,tblDrivers[sku_description],E7,tblDrivers[consumed_unit],F7) -> 0 | K7: =IFERROR(H7/G7,0) -> 1.5500004e-05 | L7: =IFERROR(J7/I7,0) -> 0 | M7: =IF(I7=0,0,(G7-I7)*L7) -> 0 | N7: =IF(I7=0,0,G7*(K7-L7)) -> 0 | O7: =IF(AND(I7=0,G7>0),H7,0) -> 134.9861 | P7: =H7-J7 -> 134.9861 | Q7: =P7-(M7+N7+O7) -> 0 | R7: =IF(O7<>0,"Scope",IF(ABS(M7)>=ABS(N7),"Usage","Rate")) -> Scope
A8: 46082 | B8: AWS | C8: Checkout | D8: AmazonCloudWatch | E8: DataProcessing-Bytes | F8: GB | G8: 212.4198 | H8: 97.7131 | I8: =SUMIFS(tblDrivers[current_quantity],tblDrivers[billing_month],EDATE(A8,-1),tblDrivers[provider_name],B8,tblDrivers[application],C8,tblDrivers[service_name],D8,tblDrivers[sku_description],E8,tblDrivers[consumed_unit],F8) -> 0 | J8: =SUMIFS(tblDrivers[current_cost],tblDrivers[billing_month],EDATE(A8,-1),tblDrivers[provider_name],B8,tblDrivers[application],C8,tblDrivers[service_name],D8,tblDrivers[sku_description],E8,tblDrivers[consumed_unit],F8) -> 0 | K8: =IFERROR(H8/G8,0) -> 0.45999996 | L8: =IFERROR(J8/I8,0) -> 0 | M8: =IF(I8=0,0,(G8-I8)*L8) -> 0 | N8: =IF(I8=0,0,G8*(K8-L8)) -> 0 | O8: =IF(AND(I8=0,G8>0),H8,0) -> 97.7131 | P8: =H8-J8 -> 97.7131 | Q8: =P8-(M8+N8+O8) -> 0 | R8: =IF(O8<>0,"Scope",IF(ABS(M8)>=ABS(N8),"Usage","Rate")) -> Scope
A9: 46082 | B9: AWS | C9: Unallocated | D9: AmazonCloudWatch | E9: DataProcessing-Bytes | F9: GB | G9: 238.9244 | H9: 109.9052 | I9: =SUMIFS(tblDrivers[current_quantity],tblDrivers[billing_month],EDATE(A9,-1),tblDrivers[provider_name],B9,tblDrivers[application],C9,tblDrivers[service_name],D9,tblDrivers[sku_description],E9,tblDrivers[consumed_unit],F9) -> 0 | J9: =SUMIFS(tblDrivers[current_cost],tblDrivers[billing_month],EDATE(A9,-1),tblDrivers[provider_name],B9,tblDrivers[application],C9,tblDrivers[service_name],D9,tblDrivers[sku_description],E9,tblDrivers[consumed_unit],F9) -> 0 | K9: =IFERROR(H9/G9,0) -> 0.4599999 | L9: =IFERROR(J9/I9,0) -> 0 | M9: =IF(I9=0,0,(G9-I9)*L9) -> 0 | N9: =IF(I9=0,0,G9*(K9-L9)) -> 0 | O9: =IF(AND(I9=0,G9>0),H9,0) -> 109.9052 | P9: =H9-J9 -> 109.9052 | Q9: =P9-(M9+N9+O9) -> 0 | R9: =IF(O9<>0,"Scope",IF(ABS(M9)>=ABS(N9),"Usage","Rate")) -> Scope
A10: 46082 | B10: AWS | C10: Analytics | D10: Amazon Elastic Compute Cloud - Compute | E10: BoxUsage:m5.large | F10: Hrs | G10: 1297.9586 | H10: 109.0286 | I10: =SUMIFS(tblDrivers[current_quantity],tblDrivers[billing_month],EDATE(A10,-1),tblDrivers[provider_name],B10,tblDrivers[application],C10,tblDrivers[service_name],D10,tblDrivers[sku_description],E10,tblDrivers[consumed_unit],F10) -> 0 | J10: =SUMIFS(tblDrivers[current_cost],tblDrivers[billing_month],EDATE(A10,-1),tblDrivers[provider_name],B10,tblDrivers[application],C10,tblDrivers[service_name],D10,tblDrivers[sku_description],E10,tblDrivers[consumed_unit],F10) -> 0 | K10: =IFERROR(H10/G10,0) -> 0.08400006 | L10: =IFERROR(J10/I10,0) -> 0 | M10: =IF(I10=0,0,(G10-I10)*L10) -> 0 | N10: =IF(I10=0,0,G10*(K10-L10)) -> 0 | O10: =IF(AND(I10=0,G10>0),H10,0) -> 109.0286 | P10: =H10-J10 -> 109.0286 | Q10: =P10-(M10+N10+O10) -> 0 | R10: =IF(O10<>0,"Scope",IF(ABS(M10)>=ABS(N10),"Usage","Rate")) -> Scope
A11: 46082 | B11: AWS | C11: Analytics | D11: Amazon Simple Storage Service | E11: TimedStorage-ByteHrs | F11: GB-Mo | G11: 182.9093 | H11: 3.9325 | I11: =SUMIFS(tblDrivers[current_quantity],tblDrivers[billing_month],EDATE(A11,-1),tblDrivers[provider_name],B11,tblDrivers[application],C11,tblDrivers[service_name],D11,tblDrivers[sku_description],E11,tblDrivers[consumed_unit],F11) -> 0 | J11: =SUMIFS(tblDrivers[current_cost],tblDrivers[billing_month],EDATE(A11,-1),tblDrivers[provider_name],B11,tblDrivers[application],C11,tblDrivers[service_name],D11,tblDrivers[sku_description],E11,tblDrivers[consumed_unit],F11) -> 0 | K11: =IFERROR(H11/G11,0) -> 0.021499727 | L11: =IFERROR(J11/I11,0) -> 0 | M11: =IF(I11=0,0,(G11-I11)*L11) -> 0 | N11: =IF(I11=0,0,G11*(K11-L11)) -> 0 | O11: =IF(AND(I11=0,G11>0),H11,0) -> 3.9325 | P11: =H11-J11 -> 3.9325 | Q11: =P11-(M11+N11+O11) -> 0 | R11: =IF(O11<>0,"Scope",IF(ABS(M11)>=ABS(N11),"Usage","Rate")) -> Scope
A12: 46082 | B12: AWS | C12: Analytics | D12: Amazon Relational Database Service | E12: InstanceUsage:db.m5.large | F12: Hrs | G12: 178.9977 | H12: 30.4296 | I12: =SUMIFS(tblDrivers[current_quantity],tblDrivers[billing_month],EDATE(A12,-1),tblDrivers[provider_name],B12,tblDrivers[application],C12,tblDrivers[service_name],D12,tblDrivers[sku_description],E12,tblDrivers[consumed_unit],F12) -> 0 | J12: =SUMIFS(tblDrivers[current_cost],tblDrivers[billing_month],EDATE(A12,-1),tblDrivers[provider_name],B12,tblDrivers[application],C12,tblDrivers[service_name],D12,tblDrivers[sku_description],E12,tblDrivers[consumed_unit],F12) -> 0 | K12: =IFERROR(H12/G12,0) -> 0.16999995 | L12: =IFERROR(J12/I12,0) -> 0 | M12: =IF(I12=0,0,(G12-I12)*L12) -> 0 | N12: =IF(I12=0,0,G12*(K12-L12)) -> 0 | O12: =IF(AND(I12=0,G12>0),H12,0) -> 30.4296 | P12: =H12-J12 -> 30.4296 | Q12: =P12-(M12+N12+O12) -> 0 | R12: =IF(O12<>0,"Scope",IF(ABS(M12)>=ABS(N12),"Usage","Rate")) -> Scope
A13: 46082 | B13: AWS | C13: Analytics | D13: AWS Lambda | E13: Lambda-GB-Second | F13: GB-Seconds | G13: 3470166.9 | H13: 53.7875 | I13: =SUMIFS(tblDrivers[current_quantity],tblDrivers[billing_month],EDATE(A13,-1),tblDrivers[provider_name],B13,tblDrivers[application],C13,tblDrivers[service_name],D13,tblDrivers[sku_description],E13,tblDrivers[consumed_unit],F13) -> 0 | J13: =SUMIFS(tblDrivers[current_cost],tblDrivers[billing_month],EDATE(A13,-1),tblDrivers[provider_name],B13,tblDrivers[application],C13,tblDrivers[service_name],D13,tblDrivers[sku_description],E13,tblDrivers[consumed_unit],F13) -> 0 | K13: =IFERROR(H13/G13,0) -> 1.5499975e-05 | L13: =IFERROR(J13/I13,0) -> 0 | M13: =IF(I13=0,0,(G13-I13)*L13) -> 0 | N13: =IF(I13=0,0,G13*(K13-L13)) -> 0 | O13: =IF(AND(I13=0,G13>0),H13,0) -> 53.7875 | P13: =H13-J13 -> 53.7875 | Q13: =P13-(M13+N13+O13) -> 0 | R13: =IF(O13<>0,"Scope",IF(ABS(M13)>=ABS(N13),"Usage","Rate")) -> Scope
... A114: 46174 | B114: GCP | C114: Unallocated | D114: Compute Engine | E114: N2 Instance Core running in Americas | F114: vCPU-hours | G114: 5625.0437 | H114: 144.2824 | I114: =SUMIFS(tblDrivers[current_quantity],tblDrivers[billing_month],EDATE(A114,-1),tblDrivers[provider_name],B114,tblDrivers[application],C114,tblDrivers[service_name],D114,tblDrivers[sku_description],E114,tblDrivers[consumed_unit],F114) -> 13613.453 | J114: =SUMIFS(tblDrivers[current_cost],tblDrivers[billing_month],EDATE(A114,-1),tblDrivers[provider_name],B114,tblDrivers[application],C114,tblDrivers[service_name],D114,tblDrivers[sku_description],E114,tblDrivers[consumed_unit],F114) -> 349.185 | K114: =IFERROR(H114/G114,0) -> 0.025650005 | L114: =IFERROR(J114/I114,0) -> 0.025649995 | M114: =IF(I114=0,0,(G114-I114)*L114) -> -204.90266 | N114: =IF(I114=0,0,G114*(K114-L114)) -> 5.9911263e-05 | O114: =IF(AND(I114=0,G114>0),H114,0) -> 0 | P114: =H114-J114 -> -204.9026 | Q114: =P114-(M114+N114+O114) -> 0 | R114: =IF(O114<>0,"Scope",IF(ABS(M114)>=ABS(N114),"Usage","Rate")) -> Usage

Sheet Variance
A1: billing_month | B1: provider_name | C1: application | D1: actual_cost | E1: budget_key | F1: approved_budget | G1: variance_amount | H1: variance_pct | I1: remaining_budget | J1: budget_utilization_pct | K1: variance_status | L1: prior_month_actual | M1: mom_change_amount | N1: mom_change_pct
A2: 46113 | B2: AWS | C2: Analytics | D2: 6676.5578 | E2: 202604|AWS|Analytics | F2: =_xlfn.XLOOKUP(E2,tblBudget[budget_key],tblBudget[approved_budget],0) -> 6676.5578 | G2: =D2-F2 -> 0 | H2: =IF(F2=0,"",G2/ABS(F2)) -> 0 | I2: =F2-D2 -> 0 | J2: =IFERROR(D2/F2,0) -> 1 | K2: =IF( A2=Assumptions!$B$15, "Baseline Month", IF( F2=0, "No Budget", IF( G2>0, "Unfavorable", IF(G2<0,"Favorable","On Budget") ) ) ) -> Baseline Month | L2: =SUMIFS( tblMonthly[actual_cost], tblMonthly[billing_month],EDATE(A2,-1), tblMonthly[provider_name],B2, tblMonthly[application],C2 ) -> 283.2416 | M2: =D2-L2 -> 6393.3162 | N2: =IF(L2=0,"",M2/ABS(L2)) -> 22.571953
A3: 46113 | B3: AWS | C3: Checkout | D3: 17008.158 | E3: 202604|AWS|Checkout | F3: =_xlfn.XLOOKUP(E3,tblBudget[budget_key],tblBudget[approved_budget],0) -> 17008.158 | G3: =D3-F3 -> 0 | H3: =IF(F3=0,"",G3/ABS(F3)) -> 0 | I3: =F3-D3 -> 0 | J3: =IFERROR(D3/F3,0) -> 1 | K3: =IF( A3=Assumptions!$B$15, "Baseline Month", IF( F3=0, "No Budget", IF( G3>0, "Unfavorable", IF(G3<0,"Favorable","On Budget") ) ) ) -> Baseline Month | L3: =SUMIFS( tblMonthly[actual_cost], tblMonthly[billing_month],EDATE(A3,-1), tblMonthly[provider_name],B3, tblMonthly[application],C3 ) -> 364.6855 | M3: =D3-L3 -> 16643.472 | N3: =IF(L3=0,"",M3/ABS(L3)) -> 45.637878
A4: 46113 | B4: AWS | C4: Unallocated | D4: 1613.8527 | E4: 202604|AWS|Unallocated | F4: =_xlfn.XLOOKUP(E4,tblBudget[budget_key],tblBudget[approved_budget],0) -> 1613.8527 | G4: =D4-F4 -> 0 | H4: =IF(F4=0,"",G4/ABS(F4)) -> 0 | I4: =F4-D4 -> 0 | J4: =IFERROR(D4/F4,0) -> 1 | K4: =IF( A4=Assumptions!$B$15, "Baseline Month", IF( F4=0, "No Budget", IF( G4>0, "Unfavorable", IF(G4<0,"Favorable","On Budget") ) ) ) -> Baseline Month | L4: =SUMIFS( tblMonthly[actual_cost], tblMonthly[billing_month],EDATE(A4,-1), tblMonthly[provider_name],B4, tblMonthly[application],C4 ) -> 239.3016 | M4: =D4-L4 -> 1374.5511 | N4: =IF(L4=0,"",M4/ABS(L4)) -> 5.7440113
